alex@UchidaGPU:/media$ cd alesx
bash: cd: alesx: No such file or directory
alex@UchidaGPU:/media$ cd alex
alex@UchidaGPU:/media/alex$ lsblk
NAME   MAJ:MIN RM   SIZE RO TYPE MOUNTPOINT
sdb      8:16   0 931.5G  0 disk 
├─sdb2   8:18   0 899.1G  0 part /
├─sdb3   8:19   0  31.9G  0 part [SWAP]
└─sdb1   8:17   0   512M  0 part /boot/efi
sr0     11:0    1  1024M  0 rom  
sdc      8:32   0   3.7T  0 disk 
├─sdc2   8:34   0   3.6T  0 part 
├─sdc3   8:35   0     8G  0 part 
└─sdc1   8:33   0     1M  0 part 
sda      8:0    0   1.8T  0 disk 
└─sda1   8:1    0   1.8T  0 part /media/alex/TOSHIBA EXT

alex@UchidaGPU:/media/alex$ sudo mount /dev/sdc2 /media/alex/noveltydisk
[sudo] password for alex: 

alex@UchidaGPU:/media/alex$ docker ps -a
CONTAINER ID        IMAGE               COMMAND                  CREATED             STATUS                    PORTS               NAMES
bd5ab139811e        alex:deepcut        "tini -- /bin/sh -c …"   7 days ago          Exited (143) 4 days ago                       gpu1novelty
f99d3f79fd54        hello-world         "/hello"                 3 months ago        Exited (0) 3 months ago                       quizzical_kowalevski

alex@UchidaGPU:/media/alex$ docker start gpu1novelty 
gpu1novelty

alex@UchidaGPU:/media/alex$ docker exec -it gpu1novelty 
"docker exec" requires at least 2 arguments.
See 'docker exec --help'.

Usage:  docker exec [OPTIONS] CONTAINER COMMAND [ARG...] [flags]

Run a command in a running container


alex@UchidaGPU:/media/alex$ docker exec -it gpu1novelty /bin/bash

root@bd5ab139811e:/opt/caffe# cd 
root@bd5ab139811e:~# cd ..
root@bd5ab139811e:/# ls
bin   dev  home     lib    media  opt   root  sbin  sys  usr
boot  etc  jupyter  lib64  mnt    proc  run   srv   tmp  var


root@bd5ab139811e:/# cd media/
root@bd5ab139811e:/media# ls
alex


root@bd5ab139811e:/media# cd alex/noveltydisk/
DeepLabCutNovelty/ DLCNbackup/        EvaluationCode/    Videos/  

          
root@bd5ab139811e:/media# cd alex/noveltydisk/EvaluationCode/
root@bd5ab139811e:/media/alex/noveltydisk/EvaluationCode# ls
auxfun.py  Makeplots.py  pose-tensorflow-customized  __pycache__  RunAnalysisoverVideos.py


root@bd5ab139811e:/media/alex/noveltydisk/EvaluationCode# 
root@bd5ab139811e:/media/alex/noveltydisk/EvaluationCode# 
root@bd5ab139811e:/media/alex/noveltydisk/EvaluationCode# 
root@bd5ab139811e:/media/alex/noveltydisk/EvaluationCode# python3 RunAnalysisoverVideos.py 
I tensorflow/stream_executor/dso_loader.cc:135] successfully opened CUDA library libcublas.so.8.0 locally
I tensorflow/stream_executor/dso_loader.cc:135] successfully opened CUDA library libcudnn.so.5 locally
I tensorflow/stream_executor/dso_loader.cc:135] successfully opened CUDA library libcufft.so.8.0 locally
I tensorflow/stream_executor/dso_loader.cc:135] successfully opened CUDA library libcuda.so.1 locally
I tensorflow/stream_executor/dso_loader.cc:135] successfully opened CUDA library libcurand.so.8.0 locally
Imageio: 'ffmpeg.linux64' was not found on your computer; downloading it now.
Error while fetching file: <urlopen error [Errno -2] Name or service not known>.
Error while fetching file: <urlopen error [Errno -2] Name or service not known>.
^C^C^C^C^C^C^C^C^C^C^C^C^C^C^C^C^C^C^CTraceback (most recent call last):
  File "/usr/lib/python3.4/urllib/request.py", line 1182, in do_open
    h.request(req.get_method(), req.selector, req.data, headers)
  File "/usr/lib/python3.4/http/client.py", line 1125, in request
    self._send_request(method, url, body, headers)
  File "/usr/lib/python3.4/http/client.py", line 1163, in _send_request
    self.endheaders(body)
  File "/usr/lib/python3.4/http/client.py", line 1121, in endheaders
    self._send_output(message_body)
  File "/usr/lib/python3.4/http/client.py", line 951, in _send_output
    self.send(msg)
  File "/usr/lib/python3.4/http/client.py", line 886, in send
    self.connect()
  File "/usr/lib/python3.4/http/client.py", line 1260, in connect
    super().connect()
  File "/usr/lib/python3.4/http/client.py", line 863, in connect
    self.timeout, self.source_address)
  File "/usr/lib/python3.4/socket.py", line 494, in create_connection
    for res in getaddrinfo(host, port, 0, SOCK_STREAM):
  File "/usr/lib/python3.4/socket.py", line 533, in getaddrinfo
    for res in _socket.getaddrinfo(host, port, family, type, proto, flags):
socket.gaierror: [Errno -2] Name or service not known

During handling of the above exception, another exception occurred:

Traceback (most recent call last):
  File "RunAnalysisoverVideos.py", line 33, in <module>
    imageio.plugins.ffmpeg.download()
  File "/usr/local/lib/python3.4/dist-packages/imageio/plugins/ffmpeg.py", line 55, in download
    get_remote_file('ffmpeg/' + FNAME_PER_PLATFORM[plat])
  File "/usr/local/lib/python3.4/dist-packages/imageio/core/fetching.py", line 121, in get_remote_file
    _fetch_file(url, filename)
  File "/usr/local/lib/python3.4/dist-packages/imageio/core/fetching.py", line 153, in _fetch_file
    remote_file = urlopen(url, timeout=5.)
  File "/usr/local/lib/python3.4/dist-packages/imageio/core/util.py", line 47, in urlopen
    return urlopen(*args, **kwargs)
  File "/usr/lib/python3.4/urllib/request.py", line 161, in urlopen
    return opener.open(url, data, timeout)
  File "/usr/lib/python3.4/urllib/request.py", line 463, in open
    response = self._open(req, data)
  File "/usr/lib/python3.4/urllib/request.py", line 481, in _open
    '_open', req)
  File "/usr/lib/python3.4/urllib/request.py", line 441, in _call_chain
    result = func(*args)
  File "/usr/lib/python3.4/urllib/request.py", line 1225, in https_open
    context=self._context, check_hostname=self._check_hostname)
  File "/usr/lib/python3.4/urllib/request.py", line 1182, in do_open
    h.request(req.get_method(), req.selector, req.data, headers)
KeyboardInterrupt

root@bd5ab139811e:/media/alex/noveltydisk/EvaluationCode# python3 RunAnalysisoverVideos.py 
I tensorflow/stream_executor/dso_loader.cc:135] successfully opened CUDA library libcublas.so.8.0 locally
I tensorflow/stream_executor/dso_loader.cc:135] successfully opened CUDA library libcudnn.so.5 locally
I tensorflow/stream_executor/dso_loader.cc:135] successfully opened CUDA library libcufft.so.8.0 locally
I tensorflow/stream_executor/dso_loader.cc:135] successfully opened CUDA library libcuda.so.1 locally
I tensorflow/stream_executor/dso_loader.cc:135] successfully opened CUDA library libcurand.so.8.0 locally
Imageio: 'ffmpeg.linux64' was not found on your computer; downloading it now.
^C^CTraceback (most recent call last):
  File "/usr/lib/python3.4/urllib/request.py", line 1182, in do_open
    h.request(req.get_method(), req.selector, req.data, headers)
  File "/usr/lib/python3.4/http/client.py", line 1125, in request
    self._send_request(method, url, body, headers)
  File "/usr/lib/python3.4/http/client.py", line 1163, in _send_request
    self.endheaders(body)
  File "/usr/lib/python3.4/http/client.py", line 1121, in endheaders
    self._send_output(message_body)
  File "/usr/lib/python3.4/http/client.py", line 951, in _send_output
    self.send(msg)
  File "/usr/lib/python3.4/http/client.py", line 886, in send
    self.connect()
  File "/usr/lib/python3.4/http/client.py", line 1260, in connect
    super().connect()
  File "/usr/lib/python3.4/http/client.py", line 863, in connect
    self.timeout, self.source_address)
  File "/usr/lib/python3.4/socket.py", line 494, in create_connection
    for res in getaddrinfo(host, port, 0, SOCK_STREAM):
  File "/usr/lib/python3.4/socket.py", line 533, in getaddrinfo
    for res in _socket.getaddrinfo(host, port, family, type, proto, flags):
socket.gaierror: [Errno -2] Name or service not known

During handling of the above exception, another exception occurred:

Traceback (most recent call last):
  File "RunAnalysisoverVideos.py", line 33, in <module>
    imageio.plugins.ffmpeg.download()
  File "/usr/local/lib/python3.4/dist-packages/imageio/plugins/ffmpeg.py", line 55, in download
    get_remote_file('ffmpeg/' + FNAME_PER_PLATFORM[plat])
  File "/usr/local/lib/python3.4/dist-packages/imageio/core/fetching.py", line 121, in get_remote_file
    _fetch_file(url, filename)
  File "/usr/local/lib/python3.4/dist-packages/imageio/core/fetching.py", line 153, in _fetch_file
    remote_file = urlopen(url, timeout=5.)
  File "/usr/local/lib/python3.4/dist-packages/imageio/core/util.py", line 47, in urlopen
    return urlopen(*args, **kwargs)
  File "/usr/lib/python3.4/urllib/request.py", line 161, in urlopen
    return opener.open(url, data, timeout)
  File "/usr/lib/python3.4/urllib/request.py", line 463, in open
    response = self._open(req, data)
  File "/usr/lib/python3.4/urllib/request.py", line 481, in _open
    '_open', req)
  File "/usr/lib/python3.4/urllib/request.py", line 441, in _call_chain
    result = func(*args)
  File "/usr/lib/python3.4/urllib/request.py", line 1225, in https_open
    context=self._context, check_hostname=self._check_hostname)
  File "/usr/lib/python3.4/urllib/request.py", line 1182, in do_open
    h.request(req.get_method(), req.selector, req.data, headers)
KeyboardInterrupt
root@bd5ab139811e:/media/alex/noveltydisk/EvaluationCode# python3
Python 3.4.3 (default, Nov 17 2016, 01:08:31) 
[GCC 4.8.4] on linux
Type "help", "copyright", "credits" or "license" for more information.
>>> import imageio
>>> imageio.plugins.ffmpeg.download()
Imageio: 'ffmpeg.linux64' was not found on your computer; downloading it now.
Error while fetching file: <urlopen error [Errno -2] Name or service not known>.
Error while fetching file: <urlopen error [Errno -2] Name or service not known>.
Error while fetching file: <urlopen error [Errno -2] Name or service not known>.
Error while fetching file: <urlopen error [Errno -2] Name or service not known>.
Traceback (most recent call last):
  File "<stdin>", line 1, in <module>
  File "/usr/local/lib/python3.4/dist-packages/imageio/plugins/ffmpeg.py", line 55, in download
    get_remote_file('ffmpeg/' + FNAME_PER_PLATFORM[plat])
  File "/usr/local/lib/python3.4/dist-packages/imageio/core/fetching.py", line 121, in get_remote_file
    _fetch_file(url, filename)
  File "/usr/local/lib/python3.4/dist-packages/imageio/core/fetching.py", line 177, in _fetch_file
    os.path.basename(file_name))
OSError: Unable to download 'ffmpeg.linux64'. Perhaps there is a no internet connection? If there is, please report this problem.
>>> exit()
root@bd5ab139811e:/media/alex/noveltydisk/EvaluationCode# 
root@bd5ab139811e:/media/alex/noveltydisk/EvaluationCode# ping google.com
ping: unknown host google.com
root@bd5ab139811e:/media/alex/noveltydisk/EvaluationCode# whereis ffmpeg
ffmpeg:
root@bd5ab139811e:/media/alex/noveltydisk/EvaluationCode# python3 RunAnalysisoverVideos.py 
I tensorflow/stream_executor/dso_loader.cc:135] successfully opened CUDA library libcublas.so.8.0 locally
I tensorflow/stream_executor/dso_loader.cc:135] successfully opened CUDA library libcudnn.so.5 locally
I tensorflow/stream_executor/dso_loader.cc:135] successfully opened CUDA library libcufft.so.8.0 locally
I tensorflow/stream_executor/dso_loader.cc:135] successfully opened CUDA library libcuda.so.1 locally
I tensorflow/stream_executor/dso_loader.cc:135] successfully opened CUDA library libcurand.so.8.0 locally
Imageio: 'ffmpeg.linux64' was not found on your computer; downloading it now.
^C^C^C^C^C^C^C^CTraceback (most recent call last):
  File "/usr/lib/python3.4/urllib/request.py", line 1182, in do_open
    h.request(req.get_method(), req.selector, req.data, headers)
  File "/usr/lib/python3.4/http/client.py", line 1125, in request
    self._send_request(method, url, body, headers)
  File "/usr/lib/python3.4/http/client.py", line 1163, in _send_request
    self.endheaders(body)
  File "/usr/lib/python3.4/http/client.py", line 1121, in endheaders
    self._send_output(message_body)
  File "/usr/lib/python3.4/http/client.py", line 951, in _send_output
    self.send(msg)
  File "/usr/lib/python3.4/http/client.py", line 886, in send
    self.connect()
  File "/usr/lib/python3.4/http/client.py", line 1260, in connect
    super().connect()
  File "/usr/lib/python3.4/http/client.py", line 863, in connect
    self.timeout, self.source_address)
  File "/usr/lib/python3.4/socket.py", line 494, in create_connection
    for res in getaddrinfo(host, port, 0, SOCK_STREAM):
  File "/usr/lib/python3.4/socket.py", line 533, in getaddrinfo
    for res in _socket.getaddrinfo(host, port, family, type, proto, flags):
socket.gaierror: [Errno -2] Name or service not known

During handling of the above exception, another exception occurred:

Traceback (most recent call last):
  File "RunAnalysisoverVideos.py", line 33, in <module>
    imageio.plugins.ffmpeg.download()
  File "/usr/local/lib/python3.4/dist-packages/imageio/plugins/ffmpeg.py", line 55, in download
    get_remote_file('ffmpeg/' + FNAME_PER_PLATFORM[plat])
  File "/usr/local/lib/python3.4/dist-packages/imageio/core/fetching.py", line 121, in get_remote_file
    _fetch_file(url, filename)
  File "/usr/local/lib/python3.4/dist-packages/imageio/core/fetching.py", line 153, in _fetch_file
    remote_file = urlopen(url, timeout=5.)
  File "/usr/local/lib/python3.4/dist-packages/imageio/core/util.py", line 47, in urlopen
    return urlopen(*args, **kwargs)
  File "/usr/lib/python3.4/urllib/request.py", line 161, in urlopen
    return opener.open(url, data, timeout)
  File "/usr/lib/python3.4/urllib/request.py", line 463, in open
    response = self._open(req, data)
  File "/usr/lib/python3.4/urllib/request.py", line 481, in _open
    '_open', req)
  File "/usr/lib/python3.4/urllib/request.py", line 441, in _call_chain
    result = func(*args)
  File "/usr/lib/python3.4/urllib/request.py", line 1225, in https_open
    context=self._context, check_hostname=self._check_hostname)
  File "/usr/lib/python3.4/urllib/request.py", line 1182, in do_open
    h.request(req.get_method(), req.selector, req.data, headers)
KeyboardInterrupt
root@bd5ab139811e:/media/alex/noveltydisk/EvaluationCode# python3 RunAnalysisoverVideos.py 
I tensorflow/stream_executor/dso_loader.cc:135] successfully opened CUDA library libcublas.so.8.0 locally
I tensorflow/stream_executor/dso_loader.cc:135] successfully opened CUDA library libcudnn.so.5 locally
I tensorflow/stream_executor/dso_loader.cc:135] successfully opened CUDA library libcufft.so.8.0 locally
I tensorflow/stream_executor/dso_loader.cc:135] successfully opened CUDA library libcuda.so.1 locally
I tensorflow/stream_executor/dso_loader.cc:135] successfully opened CUDA library libcurand.so.8.0 locally
Imageio: 'ffmpeg.linux64' was not found on your computer; downloading it now.
Error while fetching file: <urlopen error [Errno -2] Name or service not known>.
Error while fetching file: <urlopen error [Errno -2] Name or service not known>.
Error while fetching file: <urlopen error [Errno -2] Name or service not known>.
Error while fetching file: <urlopen error [Errno -2] Name or service not known>.
Traceback (most recent call last):
  File "RunAnalysisoverVideos.py", line 33, in <module>
    imageio.plugins.ffmpeg.download()
  File "/usr/local/lib/python3.4/dist-packages/imageio/plugins/ffmpeg.py", line 55, in download
    get_remote_file('ffmpeg/' + FNAME_PER_PLATFORM[plat])
  File "/usr/local/lib/python3.4/dist-packages/imageio/core/fetching.py", line 121, in get_remote_file
    _fetch_file(url, filename)
  File "/usr/local/lib/python3.4/dist-packages/imageio/core/fetching.py", line 177, in _fetch_file
    os.path.basename(file_name))
OSError: Unable to download 'ffmpeg.linux64'. Perhaps there is a no internet connection? If there is, please report this problem.
root@bd5ab139811e:/media/alex/noveltydisk/EvaluationCode# python3 RunAnalysisoverVideos.py 
I tensorflow/stream_executor/dso_loader.cc:135] successfully opened CUDA library libcublas.so.8.0 locally
I tensorflow/stream_executor/dso_loader.cc:135] successfully opened CUDA library libcudnn.so.5 locally
I tensorflow/stream_executor/dso_loader.cc:135] successfully opened CUDA library libcufft.so.8.0 locally
I tensorflow/stream_executor/dso_loader.cc:135] successfully opened CUDA library libcuda.so.1 locally
I tensorflow/stream_executor/dso_loader.cc:135] successfully opened CUDA library libcurand.so.8.0 locally
Imageio: 'ffmpeg.linux64' was not found on your computer; downloading it now.
Error while fetching file: <urlopen error [Errno -2] Name or service not known>.
Error while fetching file: <urlopen error [Errno -2] Name or service not known>.
Error while fetching file: <urlopen error [Errno -2] Name or service not known>.
Error while fetching file: <urlopen error [Errno -2] Name or service not known>.
Traceback (most recent call last):
  File "RunAnalysisoverVideos.py", line 33, in <module>
    imageio.plugins.ffmpeg.download()
  File "/usr/local/lib/python3.4/dist-packages/imageio/plugins/ffmpeg.py", line 55, in download
    get_remote_file('ffmpeg/' + FNAME_PER_PLATFORM[plat])
  File "/usr/local/lib/python3.4/dist-packages/imageio/core/fetching.py", line 121, in get_remote_file
    _fetch_file(url, filename)
  File "/usr/local/lib/python3.4/dist-packages/imageio/core/fetching.py", line 177, in _fetch_file
    os.path.basename(file_name))
OSError: Unable to download 'ffmpeg.linux64'. Perhaps there is a no internet connection? If there is, please report this problem.
root@bd5ab139811e:/media/alex/noveltydisk/EvaluationCode# docker --vesion
bash: docker: command not found
root@bd5ab139811e:/media/alex/noveltydisk/EvaluationCode# 

